2021-07-17 14:27:18,205	File already exists: /var/loadtest/logs/2021-07-17_14-26-12.491043/phantom_stdout_stderr_i1YX17.log
2021-07-17 14:27:18,206	File already exists: /var/loadtest/logs/2021-07-17_14-26-12.491043/phantom_Lpr_C3.log
2021-07-17 14:27:18,206	File not found to collect: validation_error.yaml
2021-07-17 14:27:18,207	File already exists: /var/loadtest/logs/2021-07-17_14-26-12.491043/phout_bYr8j4.log
2021-07-17 14:27:18,207	File already exists: /var/loadtest/logs/2021-07-17_14-26-12.491043/phantom_stat_OSLWwX.log
2021-07-17 14:27:18,208	File already exists: /var/loadtest/logs/2021-07-17_14-26-12.491043/answ_0ClD4D.log
2021-07-17 14:27:18,208	File already exists: /var/loadtest/logs/2021-07-17_14-26-12.491043/phantom_0HAO3V.conf
2021-07-17 14:36:54,659	Exception occurred:
<type 'exceptions.ValueError'>: invalid literal for int() with base 10: '//online.sim.s3-website-us-west-2.amazonaws.com'
  File "/usr/local/lib/python2.7/dist-packages/yandextank/core/consoleworker.py", line 375, in run
    self.core.plugins_configure()

  File "/usr/local/lib/python2.7/dist-packages/yandextank/core/tankcore.py", line 245, in plugins_configure
    plugin.configure()

  File "/usr/local/lib/python2.7/dist-packages/yandextank/plugins/Phantom/plugin.py", line 72, in configure
    self.phantom_config = self.phantom.config_file

  File "/usr/local/lib/python2.7/dist-packages/yandextank/plugins/Phantom/plugin.py", line 81, in phantom
    self._phantom.read_config()

  File "/usr/local/lib/python2.7/dist-packages/yandextank/plugins/Phantom/utils.py", line 95, in read_config
    stream.read_config()

  File "/usr/local/lib/python2.7/dist-packages/yandextank/plugins/Phantom/utils.py", line 275, in read_config
    self.address, do_test_connect, explicit_port)

  File "/usr/local/lib/python2.7/dist-packages/yandextank/common/util.py", line 521, in resolve
    port = int(parts[1])

2021-07-17 14:36:54,659	Job number is not available yet
2021-07-17 14:36:54,659	Job number is not available yet
2021-07-17 14:36:54,662	File already exists: /var/loadtest/logs/2021-07-17_14-36-54.620598/answ_ipEUxQ.log
2021-07-17 14:36:54,662	File not found to collect: validation_error.yaml
2021-07-17 14:36:54,662	File already exists: /var/loadtest/logs/2021-07-17_14-36-54.620598/phantom_1RnmlX.log
2021-07-17 14:36:54,663	File already exists: /var/loadtest/logs/2021-07-17_14-36-54.620598/phantom_stat_RLnkW5.log
2021-07-17 14:36:54,663	File already exists: /var/loadtest/logs/2021-07-17_14-36-54.620598/phout_3xbCoh.log
2021-07-17 14:39:19,256	File already exists: /var/loadtest/logs/2021-07-17_14-38-12.552103/phantom_ZiVZjw.conf
2021-07-17 14:39:19,257	File already exists: /var/loadtest/logs/2021-07-17_14-38-12.552103/phantom_stat_VDOo4A.log
2021-07-17 14:39:19,257	File already exists: /var/loadtest/logs/2021-07-17_14-38-12.552103/answ_qTSBnu.log
2021-07-17 14:39:19,257	File already exists: /var/loadtest/logs/2021-07-17_14-38-12.552103/phantom_P9EmBf.log
2021-07-17 14:39:19,258	File not found to collect: validation_error.yaml
2021-07-17 14:39:19,258	File already exists: /var/loadtest/logs/2021-07-17_14-38-12.552103/phout_lbui0B.log
2021-07-17 14:39:19,259	File already exists: /var/loadtest/logs/2021-07-17_14-38-12.552103/phantom_stdout_stderr_PPKi68.log
2021-07-17 14:50:33,471	Exception occurred:
<type 'exceptions.RuntimeError'>: All connection attempts failed for www.online.sim.s3-website-us-west-2.amazonaws.com, use {phantom.connection_test: false} to disable it
  File "/usr/local/lib/python2.7/dist-packages/yandextank/core/consoleworker.py", line 375, in run
    self.core.plugins_configure()

  File "/usr/local/lib/python2.7/dist-packages/yandextank/core/tankcore.py", line 245, in plugins_configure
    plugin.configure()

  File "/usr/local/lib/python2.7/dist-packages/yandextank/plugins/Phantom/plugin.py", line 72, in configure
    self.phantom_config = self.phantom.config_file

  File "/usr/local/lib/python2.7/dist-packages/yandextank/plugins/Phantom/plugin.py", line 81, in phantom
    self._phantom.read_config()

  File "/usr/local/lib/python2.7/dist-packages/yandextank/plugins/Phantom/utils.py", line 95, in read_config
    stream.read_config()

  File "/usr/local/lib/python2.7/dist-packages/yandextank/plugins/Phantom/utils.py", line 275, in read_config
    self.address, do_test_connect, explicit_port)

  File "/usr/local/lib/python2.7/dist-packages/yandextank/common/util.py", line 555, in resolve
    raise RuntimeError(msg % address_str)

2021-07-17 14:50:33,472	Job number is not available yet
2021-07-17 14:50:33,472	Job number is not available yet
2021-07-17 14:50:33,479	File already exists: /var/loadtest/logs/2021-07-17_14-50-17.973227/answ_hMsqbv.log
2021-07-17 14:50:33,479	File already exists: /var/loadtest/logs/2021-07-17_14-50-17.973227/phantom_stat_nicV50.log
2021-07-17 14:50:33,480	File not found to collect: validation_error.yaml
2021-07-17 14:50:33,480	File already exists: /var/loadtest/logs/2021-07-17_14-50-17.973227/phout_Kvahfs.log
2021-07-17 14:50:33,480	File already exists: /var/loadtest/logs/2021-07-17_14-50-17.973227/phantom__6ZgRT.log
2021-07-18 13:12:09,802	File already exists: /var/loadtest/logs/2021-07-18_13-11-03.077086/phantom_tqvzF7.conf
2021-07-18 13:12:09,804	File already exists: /var/loadtest/logs/2021-07-18_13-11-03.077086/phantom_stat_RSYYdU.log
2021-07-18 13:12:09,804	File not found to collect: validation_error.yaml
2021-07-18 13:12:09,805	File already exists: /var/loadtest/logs/2021-07-18_13-11-03.077086/answ_aIQMiN.log
2021-07-18 13:12:09,805	File already exists: /var/loadtest/logs/2021-07-18_13-11-03.077086/phantom_kbuzju.log
2021-07-18 13:12:09,805	File already exists: /var/loadtest/logs/2021-07-18_13-11-03.077086/phout_yRKXQX.log
2021-07-18 13:12:09,805	File already exists: /var/loadtest/logs/2021-07-18_13-11-03.077086/phantom_stdout_stderr_mdHdyL.log
2021-07-18 13:22:54,324	File already exists: /var/loadtest/logs/2021-07-18_13-21-47.390280/phout_VpZcKJ.log
2021-07-18 13:22:54,324	File already exists: /var/loadtest/logs/2021-07-18_13-21-47.390280/answ_CVNEd4.log
2021-07-18 13:22:54,324	File already exists: /var/loadtest/logs/2021-07-18_13-21-47.390280/phantom_TwKRLd.conf
2021-07-18 13:22:54,325	File not found to collect: validation_error.yaml
2021-07-18 13:22:54,325	File already exists: /var/loadtest/logs/2021-07-18_13-21-47.390280/phantom_stat_0KdY3b.log
2021-07-18 13:22:54,325	File already exists: /var/loadtest/logs/2021-07-18_13-21-47.390280/phantom_stdout_stderr_2mYnPZ.log
2021-07-18 13:22:54,325	File already exists: /var/loadtest/logs/2021-07-18_13-21-47.390280/phantom_LiHZUD.log
2021-07-18 13:33:15,021	File already exists: /var/loadtest/logs/2021-07-18_13-32-08.391562/phantom_stdout_stderr_DNsLUm.log
2021-07-18 13:33:15,021	File already exists: /var/loadtest/logs/2021-07-18_13-32-08.391562/phantom_OXd841.conf
2021-07-18 13:33:15,021	File already exists: /var/loadtest/logs/2021-07-18_13-32-08.391562/phantom_stat_cRSJq1.log
2021-07-18 13:33:15,021	File already exists: /var/loadtest/logs/2021-07-18_13-32-08.391562/answ_fua85N.log
2021-07-18 13:33:15,021	File already exists: /var/loadtest/logs/2021-07-18_13-32-08.391562/phout_ir139w.log
2021-07-18 13:33:15,022	File not found to collect: validation_error.yaml
2021-07-18 13:33:15,022	File already exists: /var/loadtest/logs/2021-07-18_13-32-08.391562/phantom_tgRqA9.log
2021-07-18 13:50:05,272	File already exists: /var/loadtest/logs/2021-07-18_13-48-49.286503/phantom_7LWqNY.conf
2021-07-18 13:50:05,273	File already exists: /var/loadtest/logs/2021-07-18_13-48-49.286503/phantom_stat_IDGvCg.log
2021-07-18 13:50:05,273	File already exists: /var/loadtest/logs/2021-07-18_13-48-49.286503/answ_Zj3GFb.log
2021-07-18 13:50:05,274	File not found to collect: validation_error.yaml
2021-07-18 13:50:05,274	File already exists: /var/loadtest/logs/2021-07-18_13-48-49.286503/phantom_3vRcZ2.log
2021-07-18 13:50:05,275	File already exists: /var/loadtest/logs/2021-07-18_13-48-49.286503/phantom_stdout_stderr_q0n7h2.log
2021-07-18 13:50:05,275	File already exists: /var/loadtest/logs/2021-07-18_13-48-49.286503/phout_NYpD0S.log
2021-07-18 13:52:11,635	File already exists: /var/loadtest/logs/2021-07-18_13-51-04.947570/phantom_stat_1l10hk.log
2021-07-18 13:52:11,635	File already exists: /var/loadtest/logs/2021-07-18_13-51-04.947570/phantom_AVO4L8.conf
2021-07-18 13:52:11,635	File already exists: /var/loadtest/logs/2021-07-18_13-51-04.947570/phantom_8tEEoR.log
2021-07-18 13:52:11,636	File not found to collect: validation_error.yaml
2021-07-18 13:52:11,636	File already exists: /var/loadtest/logs/2021-07-18_13-51-04.947570/phantom_stdout_stderr_4cdzIg.log
2021-07-18 13:52:11,636	File already exists: /var/loadtest/logs/2021-07-18_13-51-04.947570/phout_kX_DKM.log
2021-07-18 13:52:11,637	File already exists: /var/loadtest/logs/2021-07-18_13-51-04.947570/answ_msU4sc.log
2021-07-18 13:59:41,348	File already exists: /var/loadtest/logs/2021-07-18_13-58-29.051383/answ_b2uZJm.log
2021-07-18 13:59:41,349	File already exists: /var/loadtest/logs/2021-07-18_13-58-29.051383/phantom_QdpIQZ.log
2021-07-18 13:59:41,349	File already exists: /var/loadtest/logs/2021-07-18_13-58-29.051383/phantom_stdout_stderr_9eDQBC.log
2021-07-18 13:59:41,350	File already exists: /var/loadtest/logs/2021-07-18_13-58-29.051383/phantom_stat_pIem08.log
2021-07-18 13:59:41,350	File already exists: /var/loadtest/logs/2021-07-18_13-58-29.051383/phantom_xG40Uo.conf
2021-07-18 13:59:41,350	File not found to collect: validation_error.yaml
2021-07-18 13:59:41,351	File already exists: /var/loadtest/logs/2021-07-18_13-58-29.051383/phout_2UX5M8.log
2021-07-19 04:46:14,424	File already exists: /var/loadtest/logs/2021-07-19_04-45-07.449016/phout_JtKGX1.log
2021-07-19 04:46:14,424	File not found to collect: validation_error.yaml
2021-07-19 04:46:14,425	File already exists: /var/loadtest/logs/2021-07-19_04-45-07.449016/phantom_2wS6wE.log
2021-07-19 04:46:14,425	File already exists: /var/loadtest/logs/2021-07-19_04-45-07.449016/phantom_stdout_stderr_Fw4ZNC.log
2021-07-19 04:46:14,425	File already exists: /var/loadtest/logs/2021-07-19_04-45-07.449016/phantom_stat_rqgJmW.log
2021-07-19 04:46:14,426	File already exists: /var/loadtest/logs/2021-07-19_04-45-07.449016/phantom_QFFZff.conf
2021-07-19 04:46:14,426	File already exists: /var/loadtest/logs/2021-07-19_04-45-07.449016/answ_u1co2o.log
2021-07-19 04:57:11,996	File already exists: /var/loadtest/logs/2021-07-19_04-56-00.341413/phantom_2a3Y1b.log
2021-07-19 04:57:11,997	File already exists: /var/loadtest/logs/2021-07-19_04-56-00.341413/phantom_stdout_stderr_dpJQLN.log
2021-07-19 04:57:11,997	File not found to collect: validation_error.yaml
2021-07-19 04:57:11,998	File already exists: /var/loadtest/logs/2021-07-19_04-56-00.341413/phantom_stat_DOXc_k.log
2021-07-19 04:57:11,998	File already exists: /var/loadtest/logs/2021-07-19_04-56-00.341413/answ_3maZ6M.log
2021-07-19 04:57:11,999	File already exists: /var/loadtest/logs/2021-07-19_04-56-00.341413/phantom_SRm_cJ.conf
2021-07-19 04:57:11,999	File already exists: /var/loadtest/logs/2021-07-19_04-56-00.341413/phout_LJt0Gb.log
2021-07-19 05:01:02,682	File already exists: /var/loadtest/logs/2021-07-19_04-59-47.285260/phout_DRfpaM.log
2021-07-19 05:01:02,682	File already exists: /var/loadtest/logs/2021-07-19_04-59-47.285260/phantom_Ob8gGF.conf
2021-07-19 05:01:02,683	File already exists: /var/loadtest/logs/2021-07-19_04-59-47.285260/phantom_VL8h41.log
2021-07-19 05:01:02,683	File not found to collect: validation_error.yaml
2021-07-19 05:01:02,684	File already exists: /var/loadtest/logs/2021-07-19_04-59-47.285260/phantom_stdout_stderr_HAx42W.log
2021-07-19 05:01:02,684	File already exists: /var/loadtest/logs/2021-07-19_04-59-47.285260/phantom_stat_ul9_Vp.log
2021-07-19 05:01:02,685	File already exists: /var/loadtest/logs/2021-07-19_04-59-47.285260/answ__SiFpx.log
2021-07-19 05:03:29,755	Exception occurred:
<type 'exceptions.RuntimeError'>: All connection attempts failed for 178.248.237.139, use {phantom.connection_test: false} to disable it
  File "/usr/local/lib/python2.7/dist-packages/yandextank/core/consoleworker.py", line 375, in run
    self.core.plugins_configure()

  File "/usr/local/lib/python2.7/dist-packages/yandextank/core/tankcore.py", line 245, in plugins_configure
    plugin.configure()

  File "/usr/local/lib/python2.7/dist-packages/yandextank/plugins/Phantom/plugin.py", line 72, in configure
    self.phantom_config = self.phantom.config_file

  File "/usr/local/lib/python2.7/dist-packages/yandextank/plugins/Phantom/plugin.py", line 81, in phantom
    self._phantom.read_config()

  File "/usr/local/lib/python2.7/dist-packages/yandextank/plugins/Phantom/utils.py", line 95, in read_config
    stream.read_config()

  File "/usr/local/lib/python2.7/dist-packages/yandextank/plugins/Phantom/utils.py", line 275, in read_config
    self.address, do_test_connect, explicit_port)

  File "/usr/local/lib/python2.7/dist-packages/yandextank/common/util.py", line 555, in resolve
    raise RuntimeError(msg % address_str)

2021-07-19 05:03:29,756	Job number is not available yet
2021-07-19 05:03:29,756	Job number is not available yet
2021-07-19 05:03:29,760	File already exists: /var/loadtest/logs/2021-07-19_05-03-14.698017/answ_hCZL7M.log
2021-07-19 05:03:29,760	File already exists: /var/loadtest/logs/2021-07-19_05-03-14.698017/phantom_stat_ZLRy_q.log
2021-07-19 05:03:29,761	File not found to collect: validation_error.yaml
2021-07-19 05:03:29,761	File already exists: /var/loadtest/logs/2021-07-19_05-03-14.698017/phantom_hJPec3.log
2021-07-19 05:03:29,761	File already exists: /var/loadtest/logs/2021-07-19_05-03-14.698017/phout_2SqzFC.log
2021-07-19 05:04:20,249	Exception occurred:
<type 'exceptions.RuntimeError'>: All connection attempts failed for 178.248.237.139, use {phantom.connection_test: false} to disable it
  File "/usr/local/lib/python2.7/dist-packages/yandextank/core/consoleworker.py", line 375, in run
    self.core.plugins_configure()

  File "/usr/local/lib/python2.7/dist-packages/yandextank/core/tankcore.py", line 245, in plugins_configure
    plugin.configure()

  File "/usr/local/lib/python2.7/dist-packages/yandextank/plugins/Phantom/plugin.py", line 72, in configure
    self.phantom_config = self.phantom.config_file

  File "/usr/local/lib/python2.7/dist-packages/yandextank/plugins/Phantom/plugin.py", line 81, in phantom
    self._phantom.read_config()

  File "/usr/local/lib/python2.7/dist-packages/yandextank/plugins/Phantom/utils.py", line 95, in read_config
    stream.read_config()

  File "/usr/local/lib/python2.7/dist-packages/yandextank/plugins/Phantom/utils.py", line 275, in read_config
    self.address, do_test_connect, explicit_port)

  File "/usr/local/lib/python2.7/dist-packages/yandextank/common/util.py", line 555, in resolve
    raise RuntimeError(msg % address_str)

2021-07-19 05:04:20,250	Job number is not available yet
2021-07-19 05:04:20,250	Job number is not available yet
2021-07-19 05:04:20,257	File already exists: /var/loadtest/logs/2021-07-19_05-04-05.193412/phantom_TJafOI.log
2021-07-19 05:04:20,257	File not found to collect: validation_error.yaml
2021-07-19 05:04:20,257	File already exists: /var/loadtest/logs/2021-07-19_05-04-05.193412/answ_gNUiFG.log
2021-07-19 05:04:20,258	File already exists: /var/loadtest/logs/2021-07-19_05-04-05.193412/phout_Hu1Nyj.log
2021-07-19 05:04:20,258	File already exists: /var/loadtest/logs/2021-07-19_05-04-05.193412/phantom_stat_dbk1ab.log
2021-07-19 05:17:39,270	Autostop criterion requested test stop: http(5xx,10%,5s)
2021-07-19 05:17:39,274	Autostop criterion requested test stop: 5xx codes count higher than 10.0% for 5s, since 1626671851
2021-07-19 05:17:41,094	Traceback (most recent call last):
  File "/usr/local/lib/python2.7/dist-packages/yandextank/plugins/DataUploader/client.py", line 192, in __make_api_request
    response = self.__send_single_request(request, ids.next(), trace=trace)
  File "/usr/local/lib/python2.7/dist-packages/yandextank/plugins/DataUploader/client.py", line 131, in __send_single_request
    resp = self.session.send(p, timeout=self.connection_timeout)
  File "/usr/local/lib/python2.7/dist-packages/requests/sessions.py", line 646, in send
    r = adapter.send(request, **kwargs)
  File "/usr/local/lib/python2.7/dist-packages/requests/adapters.py", line 498, in send
    raise ConnectionError(err, request=request)
ConnectionError: ('Connection aborted.', BadStatusLine("''",))

2021-07-19 05:17:41,094	Network error, will retry in 10s...
2021-07-19 05:17:51,331	Failed post-processing plugin <yandextank.plugins.DataUploader.plugin.Plugin object at 0x7f0d6e666fd0>
Traceback (most recent call last):
  File "/usr/local/lib/python2.7/dist-packages/yandextank/core/tankcore.py", line 336, in plugins_post_process
    retcode = plugin.post_process(retcode)
  File "/usr/local/lib/python2.7/dist-packages/yandextank/plugins/DataUploader/plugin.py", line 373, in post_process
    int(rps), autostop.cause_criterion.explain())
  File "/usr/local/lib/python2.7/dist-packages/yandextank/plugins/DataUploader/plugin.py", line 851, in set_imbalance_and_dsc
    return self.api_client.set_imbalance_and_dsc(self.number, rps, comment)
TypeError: set_imbalance_and_dsc() takes exactly 1 argument (4 given)
2021-07-19 05:17:51,417	File already exists: /var/loadtest/logs/2021-07-19_05-17-13.678218/phout_UFTsYW.log
2021-07-19 05:17:51,418	File already exists: /var/loadtest/logs/2021-07-19_05-17-13.678218/phantom_EMoG7f.conf
2021-07-19 05:17:51,418	File already exists: /var/loadtest/logs/2021-07-19_05-17-13.678218/autostop_report.txt
2021-07-19 05:17:51,418	File already exists: /var/loadtest/logs/2021-07-19_05-17-13.678218/phantom_ey3Rez.log
2021-07-19 05:17:51,419	File already exists: /var/loadtest/logs/2021-07-19_05-17-13.678218/phantom_stat_TfLtOL.log
2021-07-19 05:17:51,419	File already exists: /var/loadtest/logs/2021-07-19_05-17-13.678218/phantom_stdout_stderr_8uZb1t.log
2021-07-19 05:17:51,419	File already exists: /var/loadtest/logs/2021-07-19_05-17-13.678218/answ_4lhPER.log
2021-07-19 05:17:51,420	File not found to collect: validation_error.yaml
2021-07-19 05:24:12,746	File not found to collect: validation_error.yaml
2021-07-19 05:24:12,746	File already exists: /var/loadtest/logs/2021-07-19_05-23-07.505264/phantom_3E4_se.log
2021-07-19 05:24:12,747	File already exists: /var/loadtest/logs/2021-07-19_05-23-07.505264/phantom_stat_zFAJeu.log
2021-07-19 05:24:12,747	File already exists: /var/loadtest/logs/2021-07-19_05-23-07.505264/answ_OOfi9Q.log
2021-07-19 05:24:12,747	File already exists: /var/loadtest/logs/2021-07-19_05-23-07.505264/phantom_xMVjOL.conf
2021-07-19 05:24:12,748	File already exists: /var/loadtest/logs/2021-07-19_05-23-07.505264/phantom_stdout_stderr_7zjTiH.log
2021-07-19 05:24:12,748	File already exists: /var/loadtest/logs/2021-07-19_05-23-07.505264/phout_qTb5HX.log
